<?xml version="1.0" ?>
<!-- =================================================================================== -->
<!-- |    This document was autogenerated by xacro from v2mini_robot.urdf.xacro        | -->
<!-- |    EDITING THIS FILE BY HAND IS NOT RECOMMENDED                                 | -->
<!-- =================================================================================== -->
<robot name="v2mini" xmlns:xacro="http://ros.org/wiki/xacro">
  <!-- v2mini body -->
  <!-- base properties -->
  <!-- wheel properties -->
  <!-- torso properties -->
  <!-- Macro for creating base wheels -->
  <!-- v2mini arm -->
  <!-- macro for the rest of the links -->
  <!-- v2mini head -->
  <!-- r200 sensor -->
  <!-- Parametring the positions -->
  <!-- Following values measured on the 3d model -->
  <!--
  Seems like this weird organization is required for move_base to work properly...
  parent > camera_rgb_frame
  -->
  <!-- join the body with head -->
  <joint name="neckpan" type="revolute">
    <parent link="torso_link"/>
    <child link="neck_link"/>
    <axis xyz="0 0 1"/>
    <origin xyz="0 0 0"/>
    <limit effort="10" lower="-2.9" upper="2.9" velocity="10"/>
  </joint>
  <!-- join the body with arm -->
  <joint name="shoulder" type="fixed">
    <parent link="torso_link"/>
    <child link="arm_link1"/>
    <origin xyz="0 0 0"/>
  </joint>
  <!-- **** BASE **** -->
  <link name="base_link">
    <!-- fake inertial values -->
    <inertial>
      <mass value="10"/>
      <inertia ixx="100" ixy="0" ixz="0" iyy="100" iyz="0" izz="100"/>
      <origin/>
    </inertial>
    <visual>
      <origin rpy="0 0 0" xyz="0 0 0.0192"/>
      <geometry>
        <mesh filename="package://v2mini_description/meshes/base/base.dae"/>
      </geometry>
    </visual>
    <collision>
      <origin rpy="0 0 0" xyz="0 0 0.066"/>
      <geometry>
        <cylinder length="0.132" radius="0.175"/>
      </geometry>
    </collision>
  </link>
  <link name="base_footprint"/>
  <joint name="base_footprint_joint" type="fixed">
    <origin rpy="0 0 0" xyz="0 0 0"/>
    <parent link="base_footprint"/>
    <child link="base_link"/>
  </joint>
  <link name="front_wheel">
    <visual>
      <origin rpy="0 0 0.0" xyz="0 0 0"/>
      <geometry>
        <mesh filename="package://v2mini_description/meshes/base/base_wheel.dae"/>
      </geometry>
    </visual>
    <inertial>
      <origin rpy="0 0 0" xyz="0 0 0"/>
      <mass value="1"/>
      <inertia ixx="1.0" ixy="0.0" ixz="0.0" iyy="1.0" iyz="0.0" izz="1.0"/>
    </inertial>
  </link>
  <joint name="front_axel" type="continuous">
    <parent link="base_link"/>
    <child link="front_wheel"/>
    <origin xyz="-0.0 -0.1405 0.03"/>
    <axis xyz="0.0 1 0"/>
  </joint>
  <link name="back_wheel">
    <visual>
      <origin rpy="0 0 3.14159" xyz="0 0 0"/>
      <geometry>
        <mesh filename="package://v2mini_description/meshes/base/base_wheel.dae"/>
      </geometry>
    </visual>
    <inertial>
      <origin rpy="0 0 0" xyz="0 0 0"/>
      <mass value="1"/>
      <inertia ixx="1.0" ixy="0.0" ixz="0.0" iyy="1.0" iyz="0.0" izz="1.0"/>
    </inertial>
  </link>
  <joint name="back_axel" type="continuous">
    <parent link="base_link"/>
    <child link="back_wheel"/>
    <origin xyz="0.0 0.1405 0.03"/>
    <axis xyz="0.0 1 0"/>
  </joint>
  <link name="right_wheel">
    <visual>
      <origin rpy="0 0 -1.570795" xyz="0 0 0"/>
      <geometry>
        <mesh filename="package://v2mini_description/meshes/base/base_wheel.dae"/>
      </geometry>
    </visual>
    <inertial>
      <origin rpy="0 0 0" xyz="0 0 0"/>
      <mass value="1"/>
      <inertia ixx="1.0" ixy="0.0" ixz="0.0" iyy="1.0" iyz="0.0" izz="1.0"/>
    </inertial>
  </link>
  <joint name="right_axel" type="continuous">
    <parent link="base_link"/>
    <child link="right_wheel"/>
    <origin xyz="-0.1405 -0.0 0.03"/>
    <axis xyz="1.0 0 0"/>
  </joint>
  <link name="left_wheel">
    <visual>
      <origin rpy="0 0 1.570795" xyz="0 0 0"/>
      <geometry>
        <mesh filename="package://v2mini_description/meshes/base/base_wheel.dae"/>
      </geometry>
    </visual>
    <inertial>
      <origin rpy="0 0 0" xyz="0 0 0"/>
      <mass value="1"/>
      <inertia ixx="1.0" ixy="0.0" ixz="0.0" iyy="1.0" iyz="0.0" izz="1.0"/>
    </inertial>
  </link>
  <joint name="left_axel" type="continuous">
    <parent link="base_link"/>
    <child link="left_wheel"/>
    <origin xyz="0.1405 0.0 0.03"/>
    <axis xyz="1.0 0 0"/>
  </joint>
  <!-- **** TORSO **** -->
  <link name="torso_link">
    <!-- fake inertial values -->
    <inertial>
      <mass value="5"/>
      <inertia ixx="100" ixy="0" ixz="0" iyy="100" iyz="0" izz="100"/>
      <origin/>
    </inertial>
    <visual>
      <origin rpy="0 0 0" xyz="0 0 0.425"/>
      <geometry>
        <mesh filename="package://v2mini_description/meshes/torso/torso.dae"/>
      </geometry>
    </visual>
  </link>
  <joint name="torso_slide" type="prismatic">
    <parent link="base_link"/>
    <child link="torso_link"/>
    <origin xyz="0 0 0"/>
    <axis xyz="0 0 1"/>
    <limit effort="10" lower="-0.09" upper="0" velocity="0.5"/>
  </joint>
  <link name="neck_link">
    <visual>
      <origin rpy="0 0 0" xyz="0 0 0.42"/>
      <geometry>
        <mesh filename="package://v2mini_description/meshes/head/neck.dae"/>
      </geometry>
    </visual>
    <inertial>
      <origin rpy="0 0 0" xyz="0 0 0"/>
      <mass value="1"/>
      <inertia ixx="1.0" ixy="0.0" ixz="0.0" iyy="1.0" iyz="0.0" izz="1.0"/>
    </inertial>
  </link>
  <link name="head_link">
    <visual>
      <origin rpy="0 0 0" xyz="0 0 0"/>
      <geometry>
        <mesh filename="package://v2mini_description/meshes/head/head.dae"/>
      </geometry>
    </visual>
    <inertial>
      <origin rpy="0 0 0" xyz="0 0 0"/>
      <mass value="1"/>
      <inertia ixx="1.0" ixy="0.0" ixz="0.0" iyy="1.0" iyz="0.0" izz="1.0"/>
    </inertial>
  </link>
  <joint name="neck_tilt" type="revolute">
    <parent link="neck_link"/>
    <child link="head_link"/>
    <axis xyz="1 0 0"/>
    <origin rpy="0 0 3.14" xyz="0 0 0.427"/>
    <limit effort="1000.0" lower="-0.5" upper="0.3" velocity="0.1"/>
  </joint>
  <!-- Attach R200 -->
  <link name="arm_link1">
    <visual>
      <origin rpy="0 0 0" xyz="0 0 0"/>
      <geometry>
        <mesh filename="package://v2mini_description/meshes/arm/arm_link1.stl"/>
      </geometry>
    </visual>
    <inertial>
      <origin rpy="0 0 0" xyz="0 0 0"/>
      <mass value="0.01"/>
      <inertia ixx="1.0" ixy="0.0" ixz="0.0" iyy="1.0" iyz="0.0" izz="1.0"/>
    </inertial>
  </link>
  <!-- first additional joint at offset -->
  <link name="arm_link2">
    <visual>
      <origin rpy="0 3.14159 0" xyz="0 0 0"/>
      <geometry>
        <mesh filename="package://v2mini_description/meshes/arm/arm_link2.stl"/>
      </geometry>
    </visual>
    <inertial>
      <origin rpy="0 0 0" xyz="0 0 0"/>
      <mass value="0.01"/>
      <inertia ixx="1.0" ixy="0.0" ixz="0.0" iyy="1.0" iyz="0.0" izz="1.0"/>
    </inertial>
  </link>
  <joint name="arm_joint1" type="continuous">
    <parent link="arm_link1"/>
    <child link="arm_link2"/>
    <origin rpy="3.14159 3.14159 0" xyz="-0.158825 -0.002 0.407507"/>
    <limit effort="1000.0" lower="-0.2" upper="2.85" velocity="0.1"/>
  </joint>
  <link name="arm_link3">
    <visual>
      <origin rpy="0 -1.570795  -1.570795" xyz="0 0 0"/>
      <geometry>
        <mesh filename="package://v2mini_description/meshes/arm/arm_link3.stl"/>
      </geometry>
    </visual>
    <inertial>
      <origin rpy="0 0 0" xyz="0 0 0"/>
      <mass value="0.01"/>
      <inertia ixx="1.0" ixy="0.0" ixz="0.0" iyy="1.0" iyz="0.0" izz="1.0"/>
    </inertial>
  </link>
  <joint name="arm_joint2" type="revolute">
    <parent link="arm_link2"/>
    <child link="arm_link3"/>
    <origin rpy="1.570795 0 4.712385" xyz="0.026 0 0"/>
    <axis xyz="-1 0 0"/>
    <limit effort="1000.0" lower="-0.3" upper="1.6" velocity="0.1"/>
  </joint>
  <link name="arm_link4">
    <visual>
      <origin rpy="1.570795 3.14159  0" xyz="0 0 0"/>
      <geometry>
        <mesh filename="package://v2mini_description/meshes/arm/arm_link4.stl"/>
      </geometry>
    </visual>
    <inertial>
      <origin rpy="0 0 0" xyz="0 0 0"/>
      <mass value="0.01"/>
      <inertia ixx="1.0" ixy="0.0" ixz="0.0" iyy="1.0" iyz="0.0" izz="1.0"/>
    </inertial>
  </link>
  <joint name="arm_joint3" type="revolute">
    <parent link="arm_link3"/>
    <child link="arm_link4"/>
    <origin rpy="0 1.570795 0" xyz=" 0 0 -0.0855"/>
    <axis xyz="1 0 0"/>
    <limit effort="1000.0" lower="-3" upper="3" velocity="0.1"/>
  </joint>
  <link name="arm_link5">
    <visual>
      <origin rpy="-1.570795 0 -1.570795" xyz="0 0 0"/>
      <geometry>
        <mesh filename="package://v2mini_description/meshes/arm/arm_link5.stl"/>
      </geometry>
    </visual>
    <inertial>
      <origin rpy="0 0 0" xyz="0 0 0"/>
      <mass value="0.01"/>
      <inertia ixx="1.0" ixy="0.0" ixz="0.0" iyy="1.0" iyz="0.0" izz="1.0"/>
    </inertial>
  </link>
  <joint name="arm_joint4" type="revolute">
    <parent link="arm_link4"/>
    <child link="arm_link5"/>
    <origin rpy=" -1.570795 0 1.570795" xyz="0.026 0 0"/>
    <axis xyz="-1 0 0"/>
    <limit effort="1000.0" lower="-1.5" upper="1.5" velocity="0.1"/>
  </joint>
  <link name="arm_link6">
    <visual>
      <origin rpy="1.570795 1.570795 0" xyz="0 0 0"/>
      <geometry>
        <mesh filename="package://v2mini_description/meshes/arm/arm_link6.stl"/>
      </geometry>
    </visual>
    <inertial>
      <origin rpy="0 0 0" xyz="0 0 0"/>
      <mass value="0.01"/>
      <inertia ixx="1.0" ixy="0.0" ixz="0.0" iyy="1.0" iyz="0.0" izz="1.0"/>
    </inertial>
  </link>
  <joint name="arm_joint5" type="revolute">
    <parent link="arm_link5"/>
    <child link="arm_link6"/>
    <origin rpy="-1.570795 -1.570795 0" xyz="0  0 -0.0415"/>
    <axis xyz="-1 0 0"/>
    <limit effort="1000.0" lower="-3" upper="3" velocity="0.1"/>
  </joint>
  <joint name="ee_joint" type="fixed">
    <parent link="arm_link6"/>
    <child link="ee_link"/>
    <origin rpy="0 0 0" xyz="0 0 0"/>
  </joint>
  <!-- Add end effector -->
  <link name="ee_link">
    <collision>
      <geometry>
        <box size="0.01 0.01 0.01"/>
      </geometry>
      <origin rpy="0 0 0" xyz="0 0 0"/>
    </collision>
    <inertial>
      <origin rpy="0 0 0" xyz="0 0 0"/>
      <mass value="1"/>
      <inertia ixx="1.0" ixy="0.0" ixz="0.0" iyy="1.0" iyz="0.0" izz="1.0"/>
    </inertial>
  </link>
</robot>

