<sdf version='1.4'>
  <model name='v2mini'>
    <link name='base_link'>
      <pose>0 0 0 0 -0 0</pose>
      <inertial>
        <pose>0 0 0 0 -0 0</pose>
        <mass>10</mass>
        <inertia>
          <ixx>100</ixx>
          <ixy>0</ixy>
          <ixz>0</ixz>
          <iyy>100</iyy>
          <iyz>0</iyz>
          <izz>100</izz>
        </inertia>
      </inertial>
      <collision name='base_link_collision'>
        <pose>0 0 0.066 0 -0 0</pose>
        <geometry>
          <cylinder>
            <length>0.132</length>
            <radius>0.175</radius>
          </cylinder>
        </geometry>
      </collision>
      <visual name='base_link_visual'>
        <pose>0 0 0.0192 0 -0 0</pose>
        <geometry>
          <mesh>
            <scale>1 1 1</scale>
            <uri>model://v2mini_description/meshes/base/base.stl</uri>
          </mesh>
        </geometry>
      </visual>
      <velocity_decay>
        <linear>0</linear>
        <angular>0</angular>
      </velocity_decay>
    </link>
    <link name='back_wheel'>
      <pose>0 0.1405 0.03 0 -0 0</pose>
      <inertial>
        <pose>0 0 0 0 -0 0</pose>
        <mass>1</mass>
        <inertia>
          <ixx>1</ixx>
          <ixy>0</ixy>
          <ixz>0</ixz>
          <iyy>1</iyy>
          <iyz>0</iyz>
          <izz>1</izz>
        </inertia>
      </inertial>
      <visual name='back_wheel_visual'>
        <pose>0 0 0 0 -0 3.14159</pose>
        <geometry>
          <mesh>
            <scale>1 1 1</scale>
            <uri>model://v2mini_description/meshes/base/base_wheel.stl</uri>
          </mesh>
        </geometry>
      </visual>
      <velocity_decay>
        <linear>0</linear>
        <angular>0</angular>
      </velocity_decay>
    </link>
    <joint name='back_axel' type='revolute'>
      <child>back_wheel</child>
      <parent>base_link</parent>
      <axis>
        <xyz>0 1 0</xyz>
        <limit>
          <lower>-1e+16</lower>
          <upper>1e+16</upper>
        </limit>
        <dynamics/>
      </axis>
    </joint>
    <link name='front_wheel'>
      <pose>0 -0.1405 0.03 0 -0 0</pose>
      <inertial>
        <pose>0 0 0 0 -0 0</pose>
        <mass>1</mass>
        <inertia>
          <ixx>1</ixx>
          <ixy>0</ixy>
          <ixz>0</ixz>
          <iyy>1</iyy>
          <iyz>0</iyz>
          <izz>1</izz>
        </inertia>
      </inertial>
      <visual name='front_wheel_visual'>
        <pose>0 0 0 0 -0 0</pose>
        <geometry>
          <mesh>
            <scale>1 1 1</scale>
            <uri>model://v2mini_description/meshes/base/base_wheel.stl</uri>
          </mesh>
        </geometry>
      </visual>
      <velocity_decay>
        <linear>0</linear>
        <angular>0</angular>
      </velocity_decay>
    </link>
    <joint name='front_axel' type='revolute'>
      <child>front_wheel</child>
      <parent>base_link</parent>
      <axis>
        <xyz>0 1 0</xyz>
        <limit>
          <lower>-1e+16</lower>
          <upper>1e+16</upper>
        </limit>
        <dynamics/>
      </axis>
    </joint>
    <link name='left_wheel'>
      <pose>0.1405 0 0.03 0 -0 0</pose>
      <inertial>
        <pose>0 0 0 0 -0 0</pose>
        <mass>1</mass>
        <inertia>
          <ixx>1</ixx>
          <ixy>0</ixy>
          <ixz>0</ixz>
          <iyy>1</iyy>
          <iyz>0</iyz>
          <izz>1</izz>
        </inertia>
      </inertial>
      <visual name='left_wheel_visual'>
        <pose>0 0 0 0 -0 1.57079</pose>
        <geometry>
          <mesh>
            <scale>1 1 1</scale>
            <uri>model://v2mini_description/meshes/base/base_wheel.stl</uri>
          </mesh>
        </geometry>
      </visual>
      <velocity_decay>
        <linear>0</linear>
        <angular>0</angular>
      </velocity_decay>
    </link>
    <joint name='left_axel' type='revolute'>
      <child>left_wheel</child>
      <parent>base_link</parent>
      <axis>
        <xyz>1 0 0</xyz>
        <limit>
          <lower>-1e+16</lower>
          <upper>1e+16</upper>
        </limit>
        <dynamics/>
      </axis>
    </joint>
    <link name='right_wheel'>
      <pose>-0.1405 0 0.03 0 -0 0</pose>
      <inertial>
        <pose>0 0 0 0 -0 0</pose>
        <mass>1</mass>
        <inertia>
          <ixx>1</ixx>
          <ixy>0</ixy>
          <ixz>0</ixz>
          <iyy>1</iyy>
          <iyz>0</iyz>
          <izz>1</izz>
        </inertia>
      </inertial>
      <visual name='right_wheel_visual'>
        <pose>0 0 0 0 0 -1.57079</pose>
        <geometry>
          <mesh>
            <scale>1 1 1</scale>
            <uri>model://v2mini_description/meshes/base/base_wheel.stl</uri>
          </mesh>
        </geometry>
      </visual>
      <velocity_decay>
        <linear>0</linear>
        <angular>0</angular>
      </velocity_decay>
    </link>
    <joint name='right_axel' type='revolute'>
      <child>right_wheel</child>
      <parent>base_link</parent>
      <axis>
        <xyz>1 0 0</xyz>
        <limit>
          <lower>-1e+16</lower>
          <upper>1e+16</upper>
        </limit>
        <dynamics/>
      </axis>
    </joint>
    <link name='torso_link'>
      <pose>0 0 0.0192 0 -0 0</pose>
      <inertial>
        <pose>0 0 0 0 -0 0</pose>
        <mass>5.01</mass>
        <inertia>
          <ixx>101</ixx>
          <ixy>0</ixy>
          <ixz>0</ixz>
          <iyy>101</iyy>
          <iyz>0</iyz>
          <izz>101</izz>
        </inertia>
      </inertial>
      <collision name='torso_link_collision_arm_link1'>
        <pose>0 0 0 0 -0 0</pose>
        <geometry>
          <mesh>
            <scale>1 1 1</scale>
            <uri>model://v2mini_description/meshes/arm/arm_link1.dae</uri>
          </mesh>
        </geometry>
      </collision>
      <visual name='torso_link_visual'>
        <pose>0 0 0 0 -0 0</pose>
        <geometry>
          <mesh>
            <scale>1 1 1</scale>
            <uri>model://v2mini_description/meshes/torso/torso.stl</uri>
          </mesh>
        </geometry>
      </visual>
      <visual name='torso_link_visual_arm_link1'>
        <pose>0 0 0 0 -0 0</pose>
        <geometry>
          <mesh>
            <scale>1 1 1</scale>
            <uri>model://v2mini_description/meshes/arm/arm_link1.dae</uri>
          </mesh>
        </geometry>
      </visual>
      <velocity_decay>
        <linear>0</linear>
        <angular>0</angular>
      </velocity_decay>
    </link>
    <joint name='torso_slide' type='prismatic'>
      <child>torso_link</child>
      <parent>base_link</parent>
      <axis>
        <xyz>0 0 1</xyz>
        <limit>
          <lower>-0.09</lower>
          <upper>0</upper>
          <effort>10</effort>
          <velocity>0.5</velocity>
        </limit>
        <dynamics/>
      </axis>
    </joint>
    <link name='neck_link'>
      <pose>0 0 0.0192 0 -0 0</pose>
      <inertial>
        <pose>0 0 0 0 -0 0</pose>
        <mass>1</mass>
        <inertia>
          <ixx>1</ixx>
          <ixy>0</ixy>
          <ixz>0</ixz>
          <iyy>1</iyy>
          <iyz>0</iyz>
          <izz>1</izz>
        </inertia>
      </inertial>
      <visual name='neck_link_visual'>
        <pose>0 0 0 0 -0 0</pose>
        <geometry>
          <mesh>
            <scale>1 1 1</scale>
            <uri>model://v2mini_description/meshes/head/neck.stl</uri>
          </mesh>
        </geometry>
      </visual>
      <velocity_decay>
        <linear>0</linear>
        <angular>0</angular>
      </velocity_decay>
    </link>
    <joint name='neckpan' type='revolute'>
      <child>neck_link</child>
      <parent>torso_link</parent>
      <axis>
        <xyz>0 0 1</xyz>
        <limit>
          <lower>-2.9</lower>
          <upper>2.9</upper>
          <effort>10</effort>
          <velocity>10</velocity>
        </limit>
        <dynamics/>
      </axis>
    </joint>
    <link name='head_link'>
      <pose>0 0 0.514415 0 -0 0</pose>
      <inertial>
        <pose>0 0 0 0 -0 0</pose>
        <mass>1</mass>
        <inertia>
          <ixx>1</ixx>
          <ixy>0</ixy>
          <ixz>0</ixz>
          <iyy>1</iyy>
          <iyz>0</iyz>
          <izz>1</izz>
        </inertia>
      </inertial>
      <visual name='head_link_visual'>
        <pose>0 0 0 0 -0 0</pose>
        <geometry>
          <mesh>
            <scale>1 1 1</scale>
            <uri>model://v2mini_description/meshes/head/head.stl</uri>
          </mesh>
        </geometry>
      </visual>
      <visual name='head_link_visual_camera_link'>
        <pose>0 -0.0668 0.0877 0 -0 0</pose>
        <geometry>
          <box>
            <size>0.102 0.0038 0.0095</size>
          </box>
        </geometry>
      </visual>
      <velocity_decay>
        <linear>0</linear>
        <angular>0</angular>
      </velocity_decay>
    </link>
    <joint name='neck_tilt' type='revolute'>
      <child>head_link</child>
      <parent>neck_link</parent>
      <axis>
        <xyz>1 0 0</xyz>
        <limit>
          <lower>-0.5</lower>
          <upper>0.3</upper>
          <effort>1000</effort>
          <velocity>0.1</velocity>
        </limit>
        <dynamics/>
      </axis>
    </joint>
    <link name='arm_link2'>
      <pose>-0.158825 -0.002 0.426707 -2.65359e-06 2.65359e-06 3.14159</pose>
      <inertial>
        <pose>0 0 0 0 -0 0</pose>
        <mass>0.01</mass>
        <inertia>
          <ixx>1</ixx>
          <ixy>0</ixy>
          <ixz>0</ixz>
          <iyy>1</iyy>
          <iyz>0</iyz>
          <izz>1</izz>
        </inertia>
      </inertial>
      <collision name='arm_link2_collision'>
        <pose>0 0 0 3.14159 2.65359e-06 3.14159</pose>
        <geometry>
          <mesh>
            <scale>1 1 1</scale>
            <uri>model://v2mini_description/meshes/arm/arm_link2.dae</uri>
          </mesh>
        </geometry>
      </collision>
      <visual name='arm_link2_visual'>
        <pose>0 0 0 3.14159 2.65359e-06 3.14159</pose>
        <geometry>
          <mesh>
            <scale>1 1 1</scale>
            <uri>model://v2mini_description/meshes/arm/arm_link2.dae</uri>
          </mesh>
        </geometry>
      </visual>
      <velocity_decay>
        <linear>0</linear>
        <angular>0</angular>
      </velocity_decay>
    </link>
    <joint name='arm_joint1' type='revolute'>
      <child>arm_link2</child>
      <parent>torso_link</parent>
      <axis>
        <xyz>-1 0 -2.65359e-06</xyz>
        <limit>
          <lower>-0.2</lower>
          <upper>2.85</upper>
          <effort>1000</effort>
          <velocity>0.1</velocity>
        </limit>
        <dynamics/>
      </axis>
    </joint>
    <link name='arm_link3'>
      <pose>-0.184825 -0.002 0.426707 1.57079 -2.6536e-06 1.57079</pose>
      <inertial>
        <pose>0 0 0 0 -0 0</pose>
        <mass>0.01</mass>
        <inertia>
          <ixx>1</ixx>
          <ixy>0</ixy>
          <ixz>0</ixz>
          <iyy>1</iyy>
          <iyz>0</iyz>
          <izz>1</izz>
        </inertia>
      </inertial>
      <collision name='arm_link3_collision'>
        <pose>0 0 0 -3.14159 -1.57079 1.57079</pose>
        <geometry>
          <mesh>
            <scale>1 1 1</scale>
            <uri>model://v2mini_description/meshes/arm/arm_link3.dae</uri>
          </mesh>
        </geometry>
      </collision>
      <visual name='arm_link3_visual'>
        <pose>0 0 0 -3.14159 -1.57079 1.57079</pose>
        <geometry>
          <mesh>
            <scale>1 1 1</scale>
            <uri>model://v2mini_description/meshes/arm/arm_link3.dae</uri>
          </mesh>
        </geometry>
      </visual>
      <velocity_decay>
        <linear>0</linear>
        <angular>0</angular>
      </velocity_decay>
    </link>
    <joint name='arm_joint2' type='revolute'>
      <child>arm_link3</child>
      <parent>arm_link2</parent>
      <axis>
        <xyz>-3.98038e-06 -1 -2.6536e-06</xyz>
        <limit>
          <lower>-0.3</lower>
          <upper>1.6</upper>
          <effort>1000</effort>
          <velocity>0.1</velocity>
        </limit>
        <dynamics/>
      </axis>
    </joint>
    <link name='arm_link4'>
      <pose>-0.270325 -0.00199966 0.426707 1.57079 3.98037e-06 3.14159</pose>
      <inertial>
        <pose>0 0 0 0 -0 0</pose>
        <mass>0.01</mass>
        <inertia>
          <ixx>1</ixx>
          <ixy>0</ixy>
          <ixz>0</ixz>
          <iyy>1</iyy>
          <iyz>0</iyz>
          <izz>1</izz>
        </inertia>
      </inertial>
      <collision name='arm_link4_collision'>
        <pose>0 0 0 -1.5708 2.65359e-06 3.14159</pose>
        <geometry>
          <mesh>
            <scale>1 1 1</scale>
            <uri>model://v2mini_description/meshes/arm/arm_link4.dae</uri>
          </mesh>
        </geometry>
      </collision>
      <visual name='arm_link4_visual'>
        <pose>0 0 0 -1.5708 2.65359e-06 3.14159</pose>
        <geometry>
          <mesh>
            <scale>1 1 1</scale>
            <uri>model://v2mini_description/meshes/arm/arm_link4.dae</uri>
          </mesh>
        </geometry>
      </visual>
      <velocity_decay>
        <linear>0</linear>
        <angular>0</angular>
      </velocity_decay>
    </link>
    <joint name='arm_joint3' type='revolute'>
      <child>arm_link4</child>
      <parent>arm_link3</parent>
      <axis>
        <xyz>-1 5.30718e-06 -3.98037e-06</xyz>
        <limit>
          <lower>-3</lower>
          <upper>3</upper>
          <effort>1000</effort>
          <velocity>0.1</velocity>
        </limit>
        <dynamics/>
      </axis>
    </joint>
    <link name='arm_link5'>
      <pose>-0.296325 -0.00199952 0.426706 -0.46365 -1.57079 -2.67795</pose>
      <inertial>
        <pose>0 0 0 0 -0 0</pose>
        <mass>0.01</mass>
        <inertia>
          <ixx>1</ixx>
          <ixy>0</ixy>
          <ixz>0</ixz>
          <iyy>1</iyy>
          <iyz>0</iyz>
          <izz>1</izz>
        </inertia>
      </inertial>
      <collision name='arm_link5_collision'>
        <pose>0 0 0 -1.57079 -0 -1.57079</pose>
        <geometry>
          <mesh>
            <scale>1 1 1</scale>
            <uri>model://v2mini_description/meshes/arm/arm_link5.dae</uri>
          </mesh>
        </geometry>
      </collision>
      <visual name='arm_link5_visual'>
        <pose>0 0 0 -1.57079 -0 -1.57079</pose>
        <geometry>
          <mesh>
            <scale>1 1 1</scale>
            <uri>model://v2mini_description/meshes/arm/arm_link5.dae</uri>
          </mesh>
        </geometry>
      </visual>
      <velocity_decay>
        <linear>0</linear>
        <angular>0</angular>
      </velocity_decay>
    </link>
    <joint name='arm_joint4' type='revolute'>
      <child>arm_link5</child>
      <parent>arm_link4</parent>
      <axis>
        <xyz>5.30718e-06 2.65358e-06 -1</xyz>
        <limit>
          <lower>-1.5</lower>
          <upper>1.5</upper>
          <effort>1000</effort>
          <velocity>0.1</velocity>
        </limit>
        <dynamics/>
      </axis>
    </joint>
    <link name='arm_link6'>
      <pose>-0.337825 -0.00199936 0.426706 1.5708 -6.63396e-06 -3.9804e-06</pose>
      <inertial>
        <pose>0 0 0 0 -0 0</pose>
        <mass>1.01</mass>
        <inertia>
          <ixx>2</ixx>
          <ixy>0</ixy>
          <ixz>0</ixz>
          <iyy>2</iyy>
          <iyz>0</iyz>
          <izz>2</izz>
        </inertia>
      </inertial>
      <collision name='arm_link6_collision'>
        <pose>0 0 0 -1.57079 1.57079 -3.14159</pose>
        <geometry>
          <mesh>
            <scale>1 1 1</scale>
            <uri>model://v2mini_description/meshes/arm/arm_link6.dae</uri>
          </mesh>
        </geometry>
      </collision>
      <collision name='arm_link6_collision_ee_link'>
        <pose>0 0 0 0 -0 0</pose>
        <geometry>
          <box>
            <size>0.01 0.01 0.01</size>
          </box>
        </geometry>
      </collision>
      <visual name='arm_link6_visual'>
        <pose>0 0 0 -1.57079 1.57079 -3.14159</pose>
        <geometry>
          <mesh>
            <scale>1 1 1</scale>
            <uri>model://v2mini_description/meshes/arm/arm_link6.dae</uri>
          </mesh>
        </geometry>
      </visual>
      <velocity_decay>
        <linear>0</linear>
        <angular>0</angular>
      </velocity_decay>
    </link>
    <joint name='arm_joint5' type='revolute'>
      <child>arm_link6</child>
      <parent>arm_link5</parent>
      <axis>
        <xyz>-1 3.9804e-06 -6.63396e-06</xyz>
        <limit>
          <lower>-3</lower>
          <upper>3</upper>
          <effort>1000</effort>
          <velocity>0.1</velocity>
        </limit>
        <dynamics/>
      </axis>
    </joint>
  </model>
</sdf>
