<?xml version="1.0"?>
<robot xmlns:xacro="http://www.ros.org/wiki/xacro" name="v2mini">

  <!-- v2mini body -->
  <include filename="$(find v2mini_description)/urdf/v2mini_body.urdf.xacro" />

  <!-- v2mini arm -->
  <include filename="$(find v2mini_description)/urdf/v2mini_arm.urdf.xacro" />

  <!-- v2mini head -->
  <include filename="$(find v2mini_description)/urdf/v2mini_head.urdf.xacro" /> 

  <!-- r200 sensor -->
  <include filename="$(find v2mini_description)/urdf/sensors/r200.urdf.xacro" />

 <!-- join the body with head -->
  <joint name="neckpan" type="revolute">
    <parent link="torso_link"/>
    <child link="neck_link"/>
    <axis xyz="0 0 1"/>
    <origin xyz="0 0 0"/>
    <limit effort="10" lower="-2.9" upper="2.9" velocity="10"/>
  </joint>

  <!-- join the body with arm -->
  <joint name="shoulder" type="fixed">
    <parent link="torso_link"/>
    <child link="arm_link1"/>
    <origin xyz="0 0 0"/>
  </joint>

  <xacro:body/>
  <xacro:head/>
  <xacro:arm/>

</robot>
