<sdf version='1.6'>
  <model name='v2mini'>
    <link name='base_footprint'>
      <pose frame=''>0 0 0 0 -0 0</pose>
      <inertial>
        <pose frame=''>0 0 0 0 -0 0</pose>
        <mass>10</mass>
        <inertia>
          <ixx>100</ixx>
          <ixy>0</ixy>
          <ixz>0</ixz>
          <iyy>100</iyy>
          <iyz>0</iyz>
          <izz>100</izz>
        </inertia>
      </inertial>
      <collision name='base_footprint_fixed_joint_lump__base_link_collision'>
        <pose frame=''>0 0 0.066 0 -0 0</pose>
        <geometry>
          <cylinder>
            <length>0.132</length>
            <radius>0.175</radius>
          </cylinder>
        </geometry>
      </collision>
      <visual name='base_footprint_fixed_joint_lump__base_link_visual'>
        <pose frame=''>0 0 0.0192 0 -0 0</pose>
        <geometry>
          <mesh>
            <scale>1 1 1</scale>
            <uri>model://v2mini_description/meshes/base/base.dae</uri>
          </mesh>
        </geometry>
      </visual>
    </link>
    <link name='back_wheel'>
      <pose frame=''>0 0.1405 0.03 0 -0 0</pose>
      <inertial>
        <pose frame=''>0 0 0 0 -0 0</pose>
        <mass>1</mass>
        <inertia>
          <ixx>1</ixx>
          <ixy>0</ixy>
          <ixz>0</ixz>
          <iyy>1</iyy>
          <iyz>0</iyz>
          <izz>1</izz>
        </inertia>
      </inertial>
      <visual name='back_wheel_visual'>
        <pose frame=''>0 0 0 0 -0 3.14159</pose>
        <geometry>
          <mesh>
            <scale>1 1 1</scale>
            <uri>model://v2mini_description/meshes/base/base_wheel.dae</uri>
          </mesh>
        </geometry>
      </visual>
    </link>
    <joint name='back_axel' type='revolute'>
      <child>back_wheel</child>
      <parent>base_footprint</parent>
      <axis>
        <xyz>0 1 0</xyz>
        <limit>
          <lower>-1e+16</lower>
          <upper>1e+16</upper>
        </limit>
        <dynamics>
          <spring_reference>0</spring_reference>
          <spring_stiffness>0</spring_stiffness>
        </dynamics>
        <use_parent_model_frame>1</use_parent_model_frame>
      </axis>
    </joint>
    <link name='front_wheel'>
      <pose frame=''>0 -0.1405 0.03 0 -0 0</pose>
      <inertial>
        <pose frame=''>0 0 0 0 -0 0</pose>
        <mass>1</mass>
        <inertia>
          <ixx>1</ixx>
          <ixy>0</ixy>
          <ixz>0</ixz>
          <iyy>1</iyy>
          <iyz>0</iyz>
          <izz>1</izz>
        </inertia>
      </inertial>
      <visual name='front_wheel_visual'>
        <pose frame=''>0 0 0 0 -0 0</pose>
        <geometry>
          <mesh>
            <scale>1 1 1</scale>
            <uri>model://v2mini_description/meshes/base/base_wheel.dae</uri>
          </mesh>
        </geometry>
      </visual>
    </link>
    <joint name='front_axel' type='revolute'>
      <child>front_wheel</child>
      <parent>base_footprint</parent>
      <axis>
        <xyz>0 1 0</xyz>
        <limit>
          <lower>-1e+16</lower>
          <upper>1e+16</upper>
        </limit>
        <dynamics>
          <spring_reference>0</spring_reference>
          <spring_stiffness>0</spring_stiffness>
        </dynamics>
        <use_parent_model_frame>1</use_parent_model_frame>
      </axis>
    </joint>
    <link name='left_wheel'>
      <pose frame=''>0.1405 0 0.03 0 -0 0</pose>
      <inertial>
        <pose frame=''>0 0 0 0 -0 0</pose>
        <mass>1</mass>
        <inertia>
          <ixx>1</ixx>
          <ixy>0</ixy>
          <ixz>0</ixz>
          <iyy>1</iyy>
          <iyz>0</iyz>
          <izz>1</izz>
        </inertia>
      </inertial>
      <visual name='left_wheel_visual'>
        <pose frame=''>0 0 0 0 -0 1.57079</pose>
        <geometry>
          <mesh>
            <scale>1 1 1</scale>
            <uri>model://v2mini_description/meshes/base/base_wheel.dae</uri>
          </mesh>
        </geometry>
      </visual>
    </link>
    <joint name='left_axel' type='revolute'>
      <child>left_wheel</child>
      <parent>base_footprint</parent>
      <axis>
        <xyz>1 0 0</xyz>
        <limit>
          <lower>-1e+16</lower>
          <upper>1e+16</upper>
        </limit>
        <dynamics>
          <spring_reference>0</spring_reference>
          <spring_stiffness>0</spring_stiffness>
        </dynamics>
        <use_parent_model_frame>1</use_parent_model_frame>
      </axis>
    </joint>
    <link name='right_wheel'>
      <pose frame=''>-0.1405 0 0.03 0 -0 0</pose>
      <inertial>
        <pose frame=''>0 0 0 0 -0 0</pose>
        <mass>1</mass>
        <inertia>
          <ixx>1</ixx>
          <ixy>0</ixy>
          <ixz>0</ixz>
          <iyy>1</iyy>
          <iyz>0</iyz>
          <izz>1</izz>
        </inertia>
      </inertial>
      <visual name='right_wheel_visual'>
        <pose frame=''>0 0 0 0 0 -1.57079</pose>
        <geometry>
          <mesh>
            <scale>1 1 1</scale>
            <uri>model://v2mini_description/meshes/base/base_wheel.dae</uri>
          </mesh>
        </geometry>
      </visual>
    </link>
    <joint name='right_axel' type='revolute'>
      <child>right_wheel</child>
      <parent>base_footprint</parent>
      <axis>
        <xyz>1 0 0</xyz>
        <limit>
          <lower>-1e+16</lower>
          <upper>1e+16</upper>
        </limit>
        <dynamics>
          <spring_reference>0</spring_reference>
          <spring_stiffness>0</spring_stiffness>
        </dynamics>
        <use_parent_model_frame>1</use_parent_model_frame>
      </axis>
    </joint>
    <link name='torso_link'>
      <pose frame=''>0 0 0 0 -0 0</pose>
      <inertial>
        <pose frame=''>0 0 0 0 -0 0</pose>
        <mass>5.01</mass>
        <inertia>
          <ixx>101</ixx>
          <ixy>0</ixy>
          <ixz>0</ixz>
          <iyy>101</iyy>
          <iyz>0</iyz>
          <izz>101</izz>
        </inertia>
      </inertial>
      <collision name='torso_link_fixed_joint_lump__arm_link1_collision'>
        <pose frame=''>0 0 0 0 -0 0</pose>
        <geometry>
          <box>
            <size>0.04 0.06 0.08</size>
          </box>
        </geometry>
      </collision>
      <visual name='torso_link_visual'>
        <pose frame=''>0 0 0.425 0 -0 0</pose>
        <geometry>
          <mesh>
            <scale>1 1 1</scale>
            <uri>model://v2mini_description/meshes/torso/torso.dae</uri>
          </mesh>
        </geometry>
      </visual>
      <visual name='torso_link_fixed_joint_lump__arm_link1_visual_1'>
        <pose frame=''>0 0 0 0 -0 0</pose>
        <geometry>
          <mesh>
            <scale>1 1 1</scale>
            <uri>model://v2mini_description/meshes/arm/arm_link1.dae</uri>
          </mesh>
        </geometry>
      </visual>
    </link>
    <joint name='torso_slide' type='prismatic'>
      <child>torso_link</child>
      <parent>base_footprint</parent>
      <axis>
        <xyz>0 0 1</xyz>
        <limit>
          <lower>-0.09</lower>
          <upper>0</upper>
          <effort>10</effort>
          <velocity>0.5</velocity>
        </limit>
        <dynamics>
          <spring_reference>0</spring_reference>
          <spring_stiffness>0</spring_stiffness>
        </dynamics>
        <use_parent_model_frame>1</use_parent_model_frame>
      </axis>
    </joint>
    <link name='neck_link'>
      <pose frame=''>0 0 0 0 -0 0</pose>
      <inertial>
        <pose frame=''>0 0 0 0 -0 0</pose>
        <mass>1</mass>
        <inertia>
          <ixx>1</ixx>
          <ixy>0</ixy>
          <ixz>0</ixz>
          <iyy>1</iyy>
          <iyz>0</iyz>
          <izz>1</izz>
        </inertia>
      </inertial>
      <visual name='neck_link_visual'>
        <pose frame=''>0 0 0.42 0 -0 0</pose>
        <geometry>
          <mesh>
            <scale>1 1 1</scale>
            <uri>model://v2mini_description/meshes/head/neck.dae</uri>
          </mesh>
        </geometry>
      </visual>
    </link>
    <joint name='neckpan' type='revolute'>
      <child>neck_link</child>
      <parent>torso_link</parent>
      <axis>
        <xyz>0 0 1</xyz>
        <limit>
          <lower>-2.9</lower>
          <upper>2.9</upper>
          <effort>10</effort>
          <velocity>10</velocity>
        </limit>
        <dynamics>
          <spring_reference>0</spring_reference>
          <spring_stiffness>0</spring_stiffness>
        </dynamics>
        <use_parent_model_frame>1</use_parent_model_frame>
      </axis>
    </joint>
    <link name='head_link'>
      <pose frame=''>0 0 0.427 0 -0 3.14</pose>
      <inertial>
        <pose frame=''>0 0 0 0 -0 0</pose>
        <mass>1</mass>
        <inertia>
          <ixx>1</ixx>
          <ixy>0</ixy>
          <ixz>0</ixz>
          <iyy>1</iyy>
          <iyz>0</iyz>
          <izz>1</izz>
        </inertia>
      </inertial>
      <collision name='head_link_collision'>
        <pose frame=''>0 0 0 0 -0 0</pose>
        <geometry>
          <box>
            <size>0 0 0</size>
          </box>
        </geometry>
      </collision>
      <visual name='head_link_visual'>
        <pose frame=''>0 0 0 0 -0 0</pose>
        <geometry>
          <mesh>
            <scale>1 1 1</scale>
            <uri>model://v2mini_description/meshes/head/head.dae</uri>
          </mesh>
        </geometry>
      </visual>
    </link>
    <joint name='neck_tilt' type='revolute'>
      <child>head_link</child>
      <parent>neck_link</parent>
      <axis>
        <xyz>-0.999999 0.001593 0</xyz>
        <limit>
          <lower>-0.5</lower>
          <upper>0.3</upper>
          <effort>1000</effort>
          <velocity>0.1</velocity>
        </limit>
        <dynamics>
          <spring_reference>0</spring_reference>
          <spring_stiffness>0</spring_stiffness>
        </dynamics>
        <use_parent_model_frame>1</use_parent_model_frame>
      </axis>
    </joint>
    <link name='arm_link2'>
      <pose frame=''>-0.158825 -0.002 0.407507 -3e-06 3e-06 3.14159</pose>
      <inertial>
        <pose frame=''>0 0 0 0 -0 0</pose>
        <mass>0.01</mass>
        <inertia>
          <ixx>1</ixx>
          <ixy>0</ixy>
          <ixz>0</ixz>
          <iyy>1</iyy>
          <iyz>0</iyz>
          <izz>1</izz>
        </inertia>
      </inertial>
      <visual name='arm_link2_visual'>
        <pose frame=''>0 0 0 3.14159 3e-06 3.14159</pose>
        <geometry>
          <mesh>
            <scale>1 1 1</scale>
            <uri>model://v2mini_description/meshes/arm/arm_link2.dae</uri>
          </mesh>
        </geometry>
      </visual>
    </link>
    <joint name='arm_joint1' type='revolute'>
      <child>arm_link2</child>
      <parent>torso_link</parent>
      <axis>
        <xyz>-1 0 -3e-06</xyz>
        <limit>
          <lower>-1e+16</lower>
          <upper>1e+16</upper>
        </limit>
        <dynamics>
          <spring_reference>0</spring_reference>
          <spring_stiffness>0</spring_stiffness>
        </dynamics>
        <use_parent_model_frame>1</use_parent_model_frame>
      </axis>
    </joint>
    <link name='arm_link3'>
      <pose frame=''>-0.184825 -0.002 0.407507 1.57079 -3e-06 1.57079</pose>
      <inertial>
        <pose frame=''>0 0 0 0 -0 0</pose>
        <mass>0.01</mass>
        <inertia>
          <ixx>1</ixx>
          <ixy>0</ixy>
          <ixz>0</ixz>
          <iyy>1</iyy>
          <iyz>0</iyz>
          <izz>1</izz>
        </inertia>
      </inertial>
      <visual name='arm_link3_visual'>
        <pose frame=''>0 0 0 3.14159 -1.57079 1.5708</pose>
        <geometry>
          <mesh>
            <scale>1 1 1</scale>
            <uri>model://v2mini_description/meshes/arm/arm_link3.dae</uri>
          </mesh>
        </geometry>
      </visual>
    </link>
    <joint name='arm_joint2' type='revolute'>
      <child>arm_link3</child>
      <parent>arm_link2</parent>
      <axis>
        <xyz>-4e-06 -1 -3e-06</xyz>
        <limit>
          <lower>-0.3</lower>
          <upper>1.6</upper>
          <effort>1000</effort>
          <velocity>0.1</velocity>
        </limit>
        <dynamics>
          <spring_reference>0</spring_reference>
          <spring_stiffness>0</spring_stiffness>
        </dynamics>
        <use_parent_model_frame>1</use_parent_model_frame>
      </axis>
    </joint>
    <link name='arm_link4'>
      <pose frame=''>-0.270325 -0.002 0.407507 1.57079 4e-06 3.14159</pose>
      <inertial>
        <pose frame=''>0 0 0 0 -0 0</pose>
        <mass>0.01</mass>
        <inertia>
          <ixx>1</ixx>
          <ixy>0</ixy>
          <ixz>0</ixz>
          <iyy>1</iyy>
          <iyz>0</iyz>
          <izz>1</izz>
        </inertia>
      </inertial>
      <visual name='arm_link4_visual'>
        <pose frame=''>0 0 0 -1.5708 3e-06 3.14159</pose>
        <geometry>
          <mesh>
            <scale>1 1 1</scale>
            <uri>model://v2mini_description/meshes/arm/arm_link4.dae</uri>
          </mesh>
        </geometry>
      </visual>
    </link>
    <joint name='arm_joint3' type='revolute'>
      <child>arm_link4</child>
      <parent>arm_link3</parent>
      <axis>
        <xyz>-1 5e-06 -4e-06</xyz>
        <limit>
          <lower>-3</lower>
          <upper>3</upper>
          <effort>1000</effort>
          <velocity>0.1</velocity>
        </limit>
        <dynamics>
          <spring_reference>0</spring_reference>
          <spring_stiffness>0</spring_stiffness>
        </dynamics>
        <use_parent_model_frame>1</use_parent_model_frame>
      </axis>
    </joint>
    <link name='arm_link5'>
      <pose frame=''>-0.296325 -0.002 0.407506 -0.46365 -1.57079 -2.67795</pose>
      <inertial>
        <pose frame=''>0 0 0 0 -0 0</pose>
        <mass>0.01</mass>
        <inertia>
          <ixx>1</ixx>
          <ixy>0</ixy>
          <ixz>0</ixz>
          <iyy>1</iyy>
          <iyz>0</iyz>
          <izz>1</izz>
        </inertia>
      </inertial>
      <visual name='arm_link5_visual'>
        <pose frame=''>0 0 0 -1.57079 -0 -1.57079</pose>
        <geometry>
          <mesh>
            <scale>1 1 1</scale>
            <uri>model://v2mini_description/meshes/arm/arm_link5.dae</uri>
          </mesh>
        </geometry>
      </visual>
    </link>
    <joint name='arm_joint4' type='revolute'>
      <child>arm_link5</child>
      <parent>arm_link4</parent>
      <axis>
        <xyz>5e-06 3e-06 -1</xyz>
        <limit>
          <lower>-1.5</lower>
          <upper>1.5</upper>
          <effort>1000</effort>
          <velocity>0.1</velocity>
        </limit>
        <dynamics>
          <spring_reference>0</spring_reference>
          <spring_stiffness>0</spring_stiffness>
        </dynamics>
        <use_parent_model_frame>1</use_parent_model_frame>
      </axis>
    </joint>
    <link name='arm_link6'>
      <pose frame=''>-0.337825 -0.001999 0.407506 1.5708 -7e-06 -4e-06</pose>
      <inertial>
        <pose frame=''>0 0 0 0 -0 0</pose>
        <mass>1.01</mass>
        <inertia>
          <ixx>2</ixx>
          <ixy>0</ixy>
          <ixz>0</ixz>
          <iyy>2</iyy>
          <iyz>0</iyz>
          <izz>2</izz>
        </inertia>
      </inertial>
      <collision name='arm_link6_fixed_joint_lump__ee_link_collision'>
        <pose frame=''>0 0 0 0 -0 0</pose>
        <geometry>
          <box>
            <size>0.01 0.01 0.01</size>
          </box>
        </geometry>
      </collision>
      <visual name='arm_link6_visual'>
        <pose frame=''>0 0 0 -3.14159 1.57079 1.57079</pose>
        <geometry>
          <mesh>
            <scale>1 1 1</scale>
            <uri>model://v2mini_description/meshes/arm/arm_link6.dae</uri>
          </mesh>
        </geometry>
      </visual>
    </link>
    <joint name='arm_joint5' type='revolute'>
      <child>arm_link6</child>
      <parent>arm_link5</parent>
      <axis>
        <xyz>-1 4e-06 -7e-06</xyz>
        <limit>
          <lower>-3</lower>
          <upper>3</upper>
          <effort>1000</effort>
          <velocity>0.1</velocity>
        </limit>
        <dynamics>
          <spring_reference>0</spring_reference>
          <spring_stiffness>0</spring_stiffness>
        </dynamics>
        <use_parent_model_frame>1</use_parent_model_frame>
      </axis>
    </joint>
    <plugin name='ros_control' filename='libgazebo_ros_control.so'>
      <robotNamespace>/</robotNamespace>
      <robotSimType>gazebo_ros_control/DefaultRobotHWSim</robotSimType>
    </plugin>
    <plugin name='object_controller' filename='libgazebo_ros_planar_move.so'>
      <commandTopic>cmd_vel</commandTopic>
      <odometryTopic>odom</odometryTopic>
      <odometryFrame>odom</odometryFrame>
      <odometryRate>20.0</odometryRate>
      <robotBaseFrame>base_footprint</robotBaseFrame>
    </plugin>
    <static>0</static>
    <plugin name='gazebo_imu' filename='libgazebo_ros_imu.so'>
      <alwaysOn>true</alwaysOn>
      <bodyName>base_footprint</bodyName>
      <topicName>imu</topicName>
      <serviceName>imu_service</serviceName>
      <gaussianNoise>0.0</gaussianNoise>
      <updateRate>20.0</updateRate>
    </plugin>
  </model>
</sdf>
